output/closed_order.txt
{'bist_time': 1663743326297788999,
 'canceled': True,
 'id': '7621969089428831819',
 'msg_type': 'A',
 'network_time': 1663743326422720999,
 'order_stack': [{               'bist_time': 1663743600170522059,
                'id': '7621969089428831819',
                'msg_type': 'D',
                'network_time': 1663743600170359093}],
 'price': 20.1,
 'qty': 2,
 'qty_not_executed': 2,
 'que_loc': 31,
 'side': 'S'}
{'bist_time': 1663743326297788999,
 'canceled': True,
 'id': '7621969089428992627',
 'msg_type': 'A',
 'network_time': 1663743326422559675,
 'order_stack': [{               'bist_time': 1663743600223220393,
                'id': '7621969089428992627',
                'msg_type': 'D',
                'network_time': 1663743600222967830}],
 'price': 19.74,
 'qty': 10000,
 'qty_not_executed': 10000,
 'que_loc': 70,
 'side': 'B'}
{'bist_time': 1663743326297788999,
 'canceled': True,
 'id': '7621969089428839231',
 'msg_type': 'A',
 'network_time': 1663743326422581364,
 'order_stack': [{               'bist_time': 1663743600378320368,
                'id': '7621969089428839231',
                'msg_type': 'D',
                'network_time': 1663743600378130078}],
 'price': 19.6,
 'qty': 2500,
 'qty_not_executed': 2500,
 'que_loc': 117,
 'side': 'B'}
{'bist_time': 1663743326297788999,
 'canceled': True,
 'id': '7621969089428680073',
 'msg_type': 'A',
 'network_time': 1663743326422962990,
 'order_stack': [{               'bist_time': 1663743600398371766,
                'id': '7621969089428680073',
                'msg_type': 'D',
                'network_time': 1663743600398109433}],
 'price': 21.2,
 'qty': 900,
 'qty_not_executed': 900,
 'que_loc': 945,
 'side': 'S'}
{'bist_time': 1663743326297788999,
 'canceled': True,
 'id': '7621969089428807380',
 'msg_type': 'A',
 'network_time': 1663743326422720999,
 'order_stack': [{               'bist_time': 1663743600399529710,
                'id': '7621969089428807380',
                'msg_type': 'D',
                'network_time': 1663743600399262387}],
 'price': 19.97,
 'qty': 1000,
 'qty_not_executed': 1000,
 'que_loc': 11,
 'side': 'S'}
{'bist_time': 1663743326297788999,
 'canceled': True,
 'id': '7621969089428731388',
 'msg_type': 'A',
 'network_time': 1663743326423065850,
 'order_stack': [{               'bist_time': 1663743600575170650,
                'id': '7621969089428731388',
                'msg_type': 'D',
                'network_time': 1663743600574963178}],
 'price': 22.08,
 'qty': 21,
 'qty_not_executed': 21,
 'que_loc': 1355,
 'side': 'S'}
{'bist_time': 1663743326297788999,
 'canceled': False,
 'id': '7621969089428963922',
 'msg_type': 'A',
 'network_time': 1663743326422720999,
 'order_stack': [{               'id': '7621969089428963922',
                'key': '76219690894289639221663743600145842219',
                'msg_type': 'E',
                'price': 19.93,
                'qty': 700,
                'qty_not_matched': 0,
                'side': 'S'}],
 'price': 19.93,
 'qty': 700,
 'qty_not_executed': 0,
 'que_loc': 1,
 'side': 'S'}
{'bist_time': 1663743326297788999,
 'canceled': False,
 'id': '7621969089428994749',
 'msg_type': 'A',
 'network_time': 1663743326422720999,
 'order_stack': [{               'id': '7621969089428994749',
                'key': '76219690894289947491663743600145842219',
                'msg_type': 'E',
                'price': 19.93,
                'qty': 900,
                'qty_not_matched': 0,
                'side': 'S'}],
 'price': 19.93,
 'qty': 900,
 'qty_not_executed': 0,
 'que_loc': 2,
 'side': 'S'}
{'bist_time': 1663743600223710785,
 'canceled': False,
 'id': '7621969089429459083',
 'msg_type': 'A',
 'network_time': 1663743600223470460,
 'order_stack': [{               'id': '7621969089429459083',
                'key': '76219690894294590831663743600232709629',
                'msg_type': 'E',
                'price': 19.93,
                'qty': 14,
                'qty_not_matched': 0,
                'side': 'B'},
                 {               'id': '7621969089429459083',
                'key': '76219690894294590831663743600575170650',
                'msg_type': 'E',
                'price': 19.93,
                'qty': 21,
                'qty_not_matched': 0,
                'side': 'B'},
                 {               'id': '7621969089429459083',
                'key': '76219690894294590831663743600578194994',
                'msg_type': 'E',
                'price': 19.93,
                'qty': 1,
                'qty_not_matched': 0,
                'side': 'B'},
                 {               'id': '7621969089429459083',
                'key': '76219690894294590831663743600652958895',
                'msg_type': 'E',
                'price': 19.93,
                'qty': 1502,
                'qty_not_matched': 0,
                'side': 'B'},
                 {               'id': '7621969089429459083',
                'key': '76219690894294590831663743600704343042',
                'msg_type': 'E',
                'price': 19.93,
                'qty': 962,
                'qty_not_matched': 0,
                'side': 'B'}],
 'price': 19.93,
 'qty': 2500,
 'qty_not_executed': 0,
 'que_loc': 1,
 'side': 'B'}
{'bist_time': 1663743600585542276,
 'canceled': False,
 'id': '7621969089429463731',
 'msg_type': 'A',
 'network_time': 1663743600585288488,
 'order_stack': [{               'id': '7621969089429463731',
                'key': '76219690894294637311663743600704343042',
                'msg_type': 'E',
                'price': 19.93,
                'qty': 2500,
                'qty_not_matched': 0,
                'side': 'B'}],
 'price': 19.93,
 'qty': 2500,
 'qty_not_executed': 0,
 'que_loc': 2,
 'side': 'B'}
{'bist_time': 1663743601074612751,
 'canceled': False,
 'id': '7621969089429466996',
 'msg_type': 'A',
 'network_time': 1663743601074349974,
 'order_stack': [{               'id': '7621969089429466996',
                'key': '76219690894294669961663743601130848327',
                'msg_type': 'E',
                'price': 19.94,
                'qty': 390,
                'qty_not_matched': 0,
                'side': 'B'}],
 'price': 19.94,
 'qty': 390,
 'qty_not_executed': 0,
 'que_loc': 1,
 'side': 'B'}
{'bist_time': 1663743600725579131,
 'canceled': False,
 'id': '7621969089429465018',
 'msg_type': 'A',
 'network_time': 1663743600725318256,
 'order_stack': [{               'id': '7621969089429465018',
                'key': '76219690894294650181663743601130848327',
                'msg_type': 'E',
                'price': 19.93,
                'qty': 30,
                'qty_not_matched': 0,
                'side': 'B'}],
 'price': 19.93,
 'qty': 30,
 'qty_not_executed': 0,
 'que_loc': 1,
 'side': 'B'}
{'bist_time': 1663743600761972805,
 'canceled': False,
 'id': '7621969089429465270',
 'msg_type': 'A',
 'network_time': 1663743600761717208,
 'order_stack': [{               'id': '7621969089429465270',
                'key': '76219690894294652701663743601130848327',
                'msg_type': 'E',
                'price': 19.93,
                'qty': 1000,
                'qty_not_matched': 0,
                'side': 'B'}],
 'price': 19.93,
 'qty': 1000,
 'qty_not_executed': 0,
 'que_loc': 2,
 'side': 'B'}
{'bist_time': 1663743600953728299,
 'canceled': False,
 'id': '7621969089429466255',
 'msg_type': 'A',
 'network_time': 1663743600953465371,
 'order_stack': [{               'id': '7621969089429466255',
                'key': '76219690894294662551663743601130848327',
                'msg_type': 'E',
                'price': 19.93,
                'qty': 30,
                'qty_not_matched': 0,
                'side': 'B'}],
 'price': 19.93,
 'qty': 30,
 'qty_not_executed': 0,
 'que_loc': 3,
 'side': 'B'}
{'bist_time': 1663743601011781398,
 'canceled': False,
 'id': '7621969089429466755',
 'msg_type': 'A',
 'network_time': 1663743601011518974,
 'order_stack': [{               'id': '7621969089429466755',
